<?xml version="1.0" encoding="utf-8"?>
<!-- This URDF was automatically created by SolidWorks to URDF Exporter! Originally created by
Stephen Brawner (brawner@gmail.com) 
     Commit Version: 1.6.0-4-g7f85cfe  Build Version: 1.6.7995.38578
     For more information, please see http://wiki.ros.org/sw_urdf_exporter -->
<robot
  name="test_urdf">
  <link
    name="base_link">
    <inertial>
      <origin
        xyz="0.0324711846224896 -0.00333014445958105 0.0286768766135694"
        rpy="0 0 0" />
      <mass
        value="0.147489959113238" />
      <inertia
        ixx="0.000168886237292445"
        ixy="3.26368461155654E-05"
        ixz="1.52349128009078E-12"
        iyy="0.000483049032662087"
        iyz="8.63712567653115E-12"
        izz="0.000649654632941916" />
    </inertial>
    <visual>
      <origin
        xyz="0 0 0"
        rpy="0 0 0" />
      <geometry>
        <mesh
          filename="package://test_urdf/meshes/base_link.STL" />
      </geometry>
      <material
        name="">
        <color
          rgba="0.945098039215686 0.752941176470588 0.172549019607843 1" />
      </material>
    </visual>
    <collision>
      <origin
        xyz="0 0 0"
        rpy="0 0 0" />
      <geometry>
        <mesh
          filename="package://test_urdf/meshes/base_link.STL" />
      </geometry>
    </collision>
  </link>
  <link
    name="Arm_Link1">
    <inertial>
      <origin
        xyz="2.6815E-05 0.0091175 -0.020889"
        rpy="0 0 0" />
      <mass
        value="0.028882" />
      <inertia
        ixx="4.4006E-06"
        ixy="5.6903E-11"
        ixz="2.8152E-11"
        iyy="1.5044E-06"
        iyz="1.1327E-08"
        izz="4.8022E-06" />
    </inertial>
    <visual>
      <origin
        xyz="0 0 0"
        rpy="0 0 0" />
      <geometry>
        <mesh
          filename="package://test_urdf/meshes/Arm_Link1.STL" />
      </geometry>
      <material
        name="">
        <color
          rgba="1 1 1 1" />
      </material>
    </visual>
    <collision>
      <origin
        xyz="0 0 0"
        rpy="0 0 0" />
      <geometry>
        <mesh
          filename="package://test_urdf/meshes/Arm_Link1.STL" />
      </geometry>
    </collision>
  </link>
  <joint
    name="Arm_Joint1"
    type="revolute">
    <origin
      xyz="0.060404 -0.0062337 0.054861"
      rpy="0 0 1.4683" />
    <parent
      link="base_link" />
    <child
      link="Arm_Link1" />
    <axis
      xyz="0 0 1" />
    <limit
      lower="-1.57"
      upper="1.57"
      effort="100"
      velocity="1" />
  </joint>
  <link
    name="Arm_Link2">
    <inertial>
      <origin
        xyz="0.0058955 0.016933 0.027677"
        rpy="0 0 0" />
      <mass
        value="0.048537" />
      <inertia
        ixx="1.7916E-05"
        ixy="-6.8524E-09"
        ixz="-1.4595E-08"
        iyy="1.5479E-05"
        iyz="2.2889E-11"
        izz="1.215E-05" />
    </inertial>
    <visual>
      <origin
        xyz="0 0 0"
        rpy="0 0 0" />
      <geometry>
        <mesh
          filename="package://test_urdf/meshes/Arm_Link2.STL" />
      </geometry>
      <material
        name="">
        <color
          rgba="0.027451 0.56471 0.94902 1" />
      </material>
    </visual>
    <collision>
      <origin
        xyz="0 0 0"
        rpy="0 0 0" />
      <geometry>
        <mesh
          filename="package://test_urdf/meshes/Arm_Link2.STL" />
      </geometry>
    </collision>
  </link>
  <joint
    name="Arm_Joint2"
    type="revolute">
    <origin
      xyz="-0.025644 -0.010471 0.030735"
      rpy="1.5708 0 1.5708" />
    <parent
      link="Arm_Link1" />
    <child
      link="Arm_Link2" />
    <axis
      xyz="0 0 1" />
    <limit
      lower="-1.57"
      upper="1.57"
      effort="100"
      velocity="1" />
  </joint>
  <link
    name="Arm_Link3">
    <inertial>
      <origin
        xyz="1.06488215298739E-05 0.020080067864054 -0.027830572781611"
        rpy="0 0 0" />
      <mass
        value="0.0397124553649746" />
      <inertia
        ixx="1.26703517720424E-05"
        ixy="-1.31235358999118E-11"
        ixz="1.1242826923262E-10"
        iyy="7.33811349506902E-06"
        iyz="3.49659885793744E-08"
        izz="8.33684907164183E-06" />
    </inertial>
    <visual>
      <origin
        xyz="0 0 0"
        rpy="0 0 0" />
      <geometry>
        <mesh
          filename="package://test_urdf/meshes/Arm_Link3.STL" />
      </geometry>
      <material
        name="">
        <color
          rgba="0.772549019607843 0.752941176470588 0.733333333333333 1" />
      </material>
    </visual>
    <collision>
      <origin
        xyz="0 0 0"
        rpy="0 0 0" />
      <geometry>
        <mesh
          filename="package://test_urdf/meshes/Arm_Link3.STL" />
      </geometry>
    </collision>
  </link>
  <joint
    name="Arm_Joint3"
    type="revolute">
    <origin
      xyz="-1.1677E-05 0.1039 -2.8292E-05"
      rpy="3.1416 0 3.1416" />
    <parent
      link="Arm_Link2" />
    <child
      link="Arm_Link3" />
    <axis
      xyz="0 0 1" />
    <limit
      lower="-1.57"
      upper="1.57"
      effort="100"
      velocity="1" />
  </joint>
  <link
    name="Arm_Link4">
    <inertial>
      <origin
        xyz="-0.0103947606283402 0.014941219111706 -0.0289511936837187"
        rpy="0 0 0" />
      <mass
        value="0.032315079118039" />
      <inertia
        ixx="3.1166163490551E-06"
        ixy="-2.17505565987683E-08"
        ixz="-2.09872061587401E-08"
        iyy="6.31788243481589E-06"
        iyz="-1.07171530037991E-10"
        izz="6.2880126569699E-06" />
    </inertial>
    <visual>
      <origin
        xyz="0 0 0"
        rpy="0 0 0" />
      <geometry>
        <mesh
          filename="package://test_urdf/meshes/Arm_Link4.STL" />
      </geometry>
      <material
        name="">
        <color
          rgba="0.772549019607843 0.752941176470588 0.733333333333333 1" />
      </material>
    </visual>
    <collision>
      <origin
        xyz="0 0 0"
        rpy="0 0 0" />
      <geometry>
        <mesh
          filename="package://test_urdf/meshes/Arm_Link4.STL" />
      </geometry>
    </collision>
  </link>
  <joint
    name="Arm_Joint4"
    type="revolute">
    <origin
      xyz="0.00073998 0.088418 -0.0512"
      rpy="3.1416 0 3.1416" />
    <parent
      link="Arm_Link3" />
    <child
      link="Arm_Link4" />
    <axis
      xyz="0 0 -1" />
    <limit
      lower="-1.57"
      upper="1.57"
      effort="100"
      velocity="1" />
  </joint>
  <link
    name="Arm_Link5">
    <inertial>
      <origin
        xyz="0.012788 -0.0019007 0.02377"
        rpy="0 0 0" />
      <mass
        value="0.02361" />
      <inertia
        ixx="3.2044E-06"
        ixy="-2.138E-08"
        ixz="1.1878E-10"
        iyy="1.4337E-06"
        iyz="2.3371E-08"
        izz="2.4447E-06" />
    </inertial>
    <visual>
      <origin
        xyz="0 0 0"
        rpy="0 0 0" />
      <geometry>
        <mesh
          filename="package://test_urdf/meshes/Arm_Link5.STL" />
      </geometry>
      <material
        name="">
        <color
          rgba="0.098039 0.098039 0.098039 1" />
      </material>
    </visual>
    <collision>
      <origin
        xyz="0 0 0"
        rpy="0 0 0" />
      <geometry>
        <mesh
          filename="package://test_urdf/meshes/Arm_Link5.STL" />
      </geometry>
    </collision>
  </link>
  <joint
    name="Arm_Joint5"
    type="revolute">
    <origin
      xyz="0 0.064253 -0.028969"
      rpy="1.5708 0 3.1416" />
    <parent
      link="Arm_Link4" />
    <child
      link="Arm_Link5" />
    <axis
      xyz="0 0 1" />
    <limit
      lower="-1.57"
      upper="1.57"
      effort="100"
      velocity="1" />
  </joint>
  <link
    name="rlink1">
    <inertial>
      <origin
        xyz="0.0046361 0.0062404 -0.00075771"
        rpy="0 0 0" />
      <mass
        value="0.0025555" />
      <inertia
        ixx="2.1864E-07"
        ixy="-1.2224E-07"
        ixz="-3.0051E-13"
        iyy="1.9585E-07"
        iyz="2.3881E-13"
        izz="3.9849E-07" />
    </inertial>
    <visual>
      <origin
        xyz="0 0 0"
        rpy="0 0 0" />
      <geometry>
        <mesh
          filename="package://test_urdf/meshes/rlink1.STL" />
      </geometry>
      <material
        name="">
        <color
          rgba="0.29804 0.29804 0.29804 1" />
      </material>
    </visual>
    <collision>
      <origin
        xyz="0 0 0"
        rpy="0 0 0" />
      <geometry>
        <mesh
          filename="package://test_urdf/meshes/rlink1.STL" />
      </geometry>
    </collision>
  </link>
  <joint
    name="Grip_Joint"
    type="revolute">
    <origin
      xyz="-0.0061769 -0.014 0.028"
      rpy="1.5708 -0.7000 -1.5708" />
    <parent
      link="Arm_Link5" />
    <child
      link="rlink1" />
    <axis
      xyz="0 0 1" />
    <limit
      lower="-1.57"
      upper="0"
      effort="100"
      velocity="1" />
  </joint>
  <link
    name="rlink2">
    <inertial>
      <origin
        xyz="-0.00775241843867022 0.0225244623142132 -0.00803643422955283"
        rpy="0 0 0" />
      <mass
        value="0.00316936780452752" />
      <inertia
        ixx="7.99590768237315E-07"
        ixy="1.49244913356862E-07"
        ixz="6.02125994623483E-14"
        iyy="6.39031578186132E-08"
        iyz="-4.7137402535162E-14"
        izz="8.45796515940262E-07" />
    </inertial>
    <visual>
      <origin
        xyz="0 0 0"
        rpy="0 0 0" />
      <geometry>
        <mesh
          filename="package://test_urdf/meshes/rlink2.STL" />
      </geometry>
      <material
        name="">
        <color
          rgba="0.298039215686275 0.298039215686275 0.298039215686275 1" />
      </material>
    </visual>
    <collision>
      <origin
        xyz="0 0 0"
        rpy="0 0 0" />
      <geometry>
        <mesh
          filename="package://test_urdf/meshes/rlink2.STL" />
      </geometry>
    </collision>
  </link>
  <joint
    name="rlink2_joint2"
    type="continuous">
    <origin
      xyz="0.01944 0.022561 0.0031272"
      rpy="0 0 -0.72000" />
    <parent
      link="rlink1" />
    <child
      link="rlink2" />
    <axis
      xyz="0 0 -1" />
    <mimic
      joint="Grip_Joint"
      multiplier="1"
      offset="0" />
  </joint>
  <link
    name="rlink3">
    <inertial>
      <origin
        xyz="0.00710070485405219 0.00851403343998985 -0.0081054016163245"
        rpy="0 0 0" />
      <mass
        value="0.00101617154686123" />
      <inertia
        ixx="6.40237996129667E-08"
        ixy="-4.69318768800583E-08"
        ixz="3.94865601722285E-14"
        iyy="4.68913908425878E-08"
        iyz="-5.05734589466237E-14"
        izz="9.94176623462886E-08" />
    </inertial>
    <visual>
      <origin
        xyz="0 0 0"
        rpy="0 0 0" />
      <geometry>
        <mesh
          filename="package://test_urdf/meshes/rlink3.STL" />
      </geometry>
      <material
        name="">
        <color
          rgba="0.298039215686275 0.298039215686275 0.298039215686275 1" />
      </material>
    </visual>
    <collision>
      <origin
        xyz="0 0 0"
        rpy="0 0 0" />
      <geometry>
        <mesh
          filename="package://test_urdf/meshes/rlink3.STL" />
      </geometry>
    </collision>
  </link>
  <joint
    name="rlink3_joint3"
    type="continuous">
    <origin
      xyz="-0.0090425 -0.0049999 0.046974"
      rpy="1.5708 -0.65000 -1.5708" />
    <parent
      link="Arm_Link5" />
    <child
      link="rlink3" />
    <axis
      xyz="0 0 -1" />
    <mimic
      joint="Grip_Joint"
      multiplier="1"
      offset="0" />
  </joint>
  <link
    name="llink1">
    <inertial>
      <origin
        xyz="-0.00396150356955052 0.00652496691242727 -0.00420920259016552"
        rpy="0 0 0" />
      <mass
        value="0.0025897240601294" />
      <inertia
        ixx="2.51857313601231E-07"
        ixy="1.20521072775352E-07"
        ixz="1.03623802702252E-13"
        iyy="1.77146546491978E-07"
        iyz="-3.21757720366707E-14"
        izz="4.05317914700043E-07" />
    </inertial>
    <visual>
      <origin
        xyz="0 0 0"
        rpy="0 0 0" />
      <geometry>
        <mesh
          filename="package://test_urdf/meshes/llink1.STL" />
      </geometry>
      <material
        name="">
        <color
          rgba="0.298039215686275 0.298039215686275 0.298039215686275 1" />
      </material>
    </visual>
    <collision>
      <origin
        xyz="0 0 0"
        rpy="0 0 0" />
      <geometry>
        <mesh
          filename="package://test_urdf/meshes/llink1.STL" />
      </geometry>
    </collision>
  </link>
  <joint
    name="llink1_joint1"
    type="continuous">
    <origin
      xyz="-0.0094254 0.014 0.028"
      rpy="1.5708 0.66000 -1.5708" />
    <parent
      link="Arm_Link5" />
    <child
      link="llink1" />
    <axis
      xyz="0 0 -1" />
    <mimic
      joint="Grip_Joint"
      multiplier="1"
      offset="0" />
  </joint>
  <link
    name="llink2">
    <inertial>
      <origin
        xyz="-0.00688632632690748 -0.0228142476892071 -0.0081577081509282"
        rpy="0 0 0" />
      <mass
        value="0.00316936780452759" />
      <inertia
        ixx="7.99590869178272E-07"
        ixy="-1.49244891855592E-07"
        ixz="-5.22462823124203E-14"
        iyy="6.39030568776609E-08"
        iyz="5.42739439276205E-14"
        izz="8.45796515940267E-07" />
    </inertial>
    <visual>
      <origin
        xyz="0 0 0"
        rpy="0 0 0" />
      <geometry>
        <mesh
          filename="package://test_urdf/meshes/llink2.STL" />
      </geometry>
      <material
        name="">
        <color
          rgba="0.298039215686275 0.298039215686275 0.298039215686275 1" />
      </material>
    </visual>
    <collision>
      <origin
        xyz="0 0 0"
        rpy="0 0 0" />
      <geometry>
        <mesh
          filename="package://test_urdf/meshes/llink2.STL" />
      </geometry>
    </collision>
  </link>
  <joint
    name="llink2_joint2"
    type="continuous">
    <origin
      xyz="-0.016301 0.023985 0"
      rpy="0 0 3.8570" />
    <parent
      link="llink1" />
    <child
      link="llink2" />
    <axis
      xyz="0 0 1" />
    <mimic
      joint="Grip_Joint"
      multiplier="1"
      offset="0" />
  </joint>
  <link
    name="llink3">
    <inertial>
      <origin
        xyz="0.0062317 -0.0091693 -0.0084883"
        rpy="0 0 0" />
      <mass
        value="0.0010162" />
      <inertia
        ixx="7.3018E-08"
        ixy="4.4358E-08"
        ixz="-2.9404E-14"
        iyy="3.7897E-08"
        iyz="5.8415E-14"
        izz="9.9418E-08" />
    </inertial>
    <visual>
      <origin
        xyz="0 0 0"
        rpy="0 0 0" />
      <geometry>
        <mesh
          filename="package://test_urdf/meshes/llink3.STL" />
      </geometry>
      <material
        name="">
        <color
          rgba="0.29804 0.29804 0.29804 1" />
      </material>
    </visual>
    <collision>
      <origin
        xyz="0 0 0"
        rpy="0 0 0" />
      <geometry>
        <mesh
          filename="package://test_urdf/meshes/llink3.STL" />
      </geometry>
    </collision>
  </link>
  <joint
    name="llink3_joint3"
    type="continuous">
    <origin
      xyz="-0.0094254 0.0050001 0.046974"
      rpy="-1.5708 -0.60000 1.5708" />
    <parent
      link="Arm_Link5" />
    <child
      link="llink3" />
    <axis
      xyz="0 0 1" />
    <mimic
      joint="Grip_Joint"
      multiplier="1"
      offset="0" />
  </joint>
</robot>